2025-03-18 08:21:29,090 - app - INFO - Flask app started
2025-03-18 08:21:30,773 - app - INFO - Flask app started
2025-03-18 08:21:44,885 - app - INFO - Registration attempt received from IP: 172.19.0.1
2025-03-18 08:21:44,938 - app - INFO - User already exists: testuser2 - registration attempt from IP: 172.19.0.1
2025-03-18 08:21:54,131 - app - INFO - Create post request from IP: 172.19.0.1
2025-03-18 08:22:00,246 - app - ERROR - Error creating post from IP 172.19.0.1: HTTPConnectionPool(host='localhost', port=9000): Max retries exceeded with url: / (Caused by NewConnectionError('<urllib3.connection.HTTPConnection object at 0x7f6926639eb0>: Failed to establish a new connection: [Errno 111] Connection refused'))
Traceback (most recent call last):
  File "/usr/local/lib/python3.13/site-packages/urllib3/connection.py", line 198, in _new_conn
    sock = connection.create_connection(
        (self._dns_host, self.port),
    ...<2 lines>...
        socket_options=self.socket_options,
    )
  File "/usr/local/lib/python3.13/site-packages/urllib3/util/connection.py", line 85, in create_connection
    raise err
  File "/usr/local/lib/python3.13/site-packages/urllib3/util/connection.py", line 73, in create_connection
    sock.connect(sa)
    ~~~~~~~~~~~~^^^^
ConnectionRefusedError: [Errno 111] Connection refused

The above exception was the direct cause of the following exception:

Traceback (most recent call last):
  File "/usr/local/lib/python3.13/site-packages/urllib3/connectionpool.py", line 787, in urlopen
    response = self._make_request(
        conn,
    ...<10 lines>...
        **response_kw,
    )
  File "/usr/local/lib/python3.13/site-packages/urllib3/connectionpool.py", line 493, in _make_request
    conn.request(
    ~~~~~~~~~~~~^
        method,
        ^^^^^^^
    ...<6 lines>...
        enforce_content_length=enforce_content_length,
        ^^^^^^^^^^^^^^^^^^^^^^^^^^^^^^^^^^^^^^^^^^^^^^
    )
    ^
  File "/usr/local/lib/python3.13/site-packages/urllib3/connection.py", line 445, in request
    self.endheaders()
    ~~~~~~~~~~~~~~~^^
  File "/usr/local/lib/python3.13/http/client.py", line 1333, in endheaders
    self._send_output(message_body, encode_chunked=encode_chunked)
    ~~~~~~~~~~~~~~~~~^^^^^^^^^^^^^^^^^^^^^^^^^^^^^^^^^^^^^^^^^^^^^
  File "/usr/local/lib/python3.13/http/client.py", line 1093, in _send_output
    self.send(msg)
    ~~~~~~~~~^^^^^
  File "/usr/local/lib/python3.13/http/client.py", line 1037, in send
    self.connect()
    ~~~~~~~~~~~~^^
  File "/usr/local/lib/python3.13/site-packages/urllib3/connection.py", line 276, in connect
    self.sock = self._new_conn()
                ~~~~~~~~~~~~~~^^
  File "/usr/local/lib/python3.13/site-packages/urllib3/connection.py", line 213, in _new_conn
    raise NewConnectionError(
        self, f"Failed to establish a new connection: {e}"
    ) from e
urllib3.exceptions.NewConnectionError: <urllib3.connection.HTTPConnection object at 0x7f6926639eb0>: Failed to establish a new connection: [Errno 111] Connection refused

The above exception was the direct cause of the following exception:

Traceback (most recent call last):
  File "/app/src/routes/post.py", line 58, in create_post
    buckets = connect_Minio_client.list_buckets()  # Returns list of Bucket objects
  File "/usr/local/lib/python3.13/site-packages/minio/api.py", line 678, in list_buckets
    response = self._execute("GET")
  File "/usr/local/lib/python3.13/site-packages/minio/api.py", line 441, in _execute
    return self._url_open(
           ~~~~~~~~~~~~~~^
        method,
        ^^^^^^^
    ...<7 lines>...
        no_body_trace=no_body_trace,
        ^^^^^^^^^^^^^^^^^^^^^^^^^^^^
    )
    ^
  File "/usr/local/lib/python3.13/site-packages/minio/api.py", line 303, in _url_open
    response = self._http.urlopen(
        method,
    ...<3 lines>...
        preload_content=preload_content,
    )
  File "/usr/local/lib/python3.13/site-packages/urllib3/poolmanager.py", line 443, in urlopen
    response = conn.urlopen(method, u.request_uri, **kw)
  File "/usr/local/lib/python3.13/site-packages/urllib3/connectionpool.py", line 871, in urlopen
    return self.urlopen(
           ~~~~~~~~~~~~^
        method,
        ^^^^^^^
    ...<13 lines>...
        **response_kw,
        ^^^^^^^^^^^^^^
    )
    ^
  File "/usr/local/lib/python3.13/site-packages/urllib3/connectionpool.py", line 871, in urlopen
    return self.urlopen(
           ~~~~~~~~~~~~^
        method,
        ^^^^^^^
    ...<13 lines>...
        **response_kw,
        ^^^^^^^^^^^^^^
    )
    ^
  File "/usr/local/lib/python3.13/site-packages/urllib3/connectionpool.py", line 871, in urlopen
    return self.urlopen(
           ~~~~~~~~~~~~^
        method,
        ^^^^^^^
    ...<13 lines>...
        **response_kw,
        ^^^^^^^^^^^^^^
    )
    ^
  [Previous line repeated 2 more times]
  File "/usr/local/lib/python3.13/site-packages/urllib3/connectionpool.py", line 841, in urlopen
    retries = retries.increment(
        method, url, error=new_e, _pool=self, _stacktrace=sys.exc_info()[2]
    )
  File "/usr/local/lib/python3.13/site-packages/urllib3/util/retry.py", line 519, in increment
    raise MaxRetryError(_pool, url, reason) from reason  # type: ignore[arg-type]
    ^^^^^^^^^^^^^^^^^^^^^^^^^^^^^^^^^^^^^^^^^^^^^^^^^^^
urllib3.exceptions.MaxRetryError: HTTPConnectionPool(host='localhost', port=9000): Max retries exceeded with url: / (Caused by NewConnectionError('<urllib3.connection.HTTPConnection object at 0x7f6926639eb0>: Failed to establish a new connection: [Errno 111] Connection refused'))

2025-03-18 08:25:04,850 - app - INFO - Flask app started
2025-03-18 08:25:06,655 - app - INFO - Flask app started
2025-03-18 08:25:40,809 - app - INFO - Create post request from IP: 172.19.0.1
2025-03-18 08:25:40,920 - app - INFO - Post created with ID: 67d92e046540ed9981bf056f by user_id: 2 from IP: 172.19.0.1
2025-03-18 08:25:56,870 - app - INFO - Create post request from IP: 172.19.0.1
2025-03-18 08:25:56,926 - app - INFO - Post created with ID: 67d92e146540ed9981bf0571 by user_id: 2 from IP: 172.19.0.1
2025-03-18 08:26:01,191 - app - INFO - Create post request from IP: 172.19.0.1
2025-03-18 08:26:01,252 - app - INFO - Post created with ID: 67d92e196540ed9981bf0573 by user_id: 2 from IP: 172.19.0.1
2025-03-18 08:26:06,094 - app - INFO - Create post request from IP: 172.19.0.1
2025-03-18 08:26:06,176 - app - INFO - Post created with ID: 67d92e1e6540ed9981bf0575 by user_id: 2 from IP: 172.19.0.1
2025-03-18 08:26:10,654 - app - INFO - Create post request from IP: 172.19.0.1
2025-03-18 08:26:10,749 - app - INFO - Post created with ID: 67d92e226540ed9981bf0577 by user_id: 2 from IP: 172.19.0.1
2025-03-18 08:26:17,210 - app - INFO - Get posts request from IP: 172.19.0.1
2025-03-18 08:26:17,233 - app - INFO - Successfully retrieved 5 posts from IP: 172.19.0.1
